<?xml version="1.0" encoding="UTF-8"?>
<testsuite errors="0" failures="1" name="res.resources.tests.ResourceTest-20200114110128" tests="8" time="0.379">
	<properties/>
	<system-out>
<![CDATA[]]>	</system-out>
	<system-err>
<![CDATA[]]>	</system-err>
	<testcase classname="res.resources.tests.ResourceTest" name="test_get_cps" time="0.011"/>
	<testcase classname="res.resources.tests.ResourceTest" name="test_get_flavors" time="0.017"/>
	<testcase classname="res.resources.tests.ResourceTest" name="test_get_networks" time="0.016"/>
	<testcase classname="res.resources.tests.ResourceTest" name="test_get_subnets" time="0.015"/>
	<testcase classname="res.resources.tests.ResourceTest" name="test_get_vnf" time="0.269"/>
	<testcase classname="res.resources.tests.ResourceTest" name="test_get_vnfs" time="0.029"/>
	<testcase classname="res.resources.tests.ResourceTest" name="test_get_volumes" time="0.012"/>
	<testcase classname="res.resources.tests.ResourceTest" name="test_get_vms" time="0.012">
		<failure message="200 != 500" type="AssertionError">
<![CDATA[Traceback (most recent call last):
  File "/root/hw/vnfres/res/res/resources/tests.py", line 178, in test_get_vms
    self.failUnlessEqual(status.HTTP_200_OK, response.status_code)
AssertionError: 200 != 500
]]>		</failure>
	</testcase>
</testsuite>
